<robot name="bobot" version="1.0">
  <joint name="HeadEff_joint" type="revolute">
    <limit lower="-3.14000" upper="3.14000" effort="0.00000" velocity="0.00000"/>
    <origin rpy="0.00000 0.00000 0.00000" xyz="2.10444 3.65079 0.00500"/>
    <parent link="head_steel_link"/>
    <child link="HeadEff_link"/>
    <axis xyz="0.00000 0.00000 1.00000"/>
  </joint>
  <joint name="lArmEff_joint" type="revolute">
    <limit lower="-3.14000" upper="3.14000" effort="0.00000" velocity="0.00000"/>
    <origin rpy="0.00000 0.00000 0.00000" xyz="0.50000 0.00000 -2.89749"/>
    <parent link="leftArm5_plast_link"/>
    <child link="lArmEff_link"/>
    <axis xyz="0.00000 1.00000 0.00000"/>
  </joint>
  <joint name="leftArm1_plast_joint" type="revolute">
    <limit lower="-0.05480" upper="0.05480" effort="0.00000" velocity="0.00000"/>
    <origin rpy="0.00000 0.00000 0.00000" xyz="-0.00000 17.49999 -6.17249"/>
    <parent link="body0_plast_white_link"/>
    <child link="leftArm1_plast_link"/>
    <axis xyz="0.00000 0.00000 1.00000"/>
  </joint>
  <joint name="leftArm2_plast_link_joint" type="revolute">
    <limit lower="-1.83400" upper="1.83400" effort="0.00000" velocity="0.00000"/>
    <origin rpy="0.00000 0.00000 0.00000" xyz="0.00000 -0.00500 -1.87501"/>
    <parent link="leftArm1_plast_link"/>
    <child link="leftArm2_plast_link"/>
    <axis xyz="1.00000 0.00000 0.00000"/>
  </joint>
  <joint name="leftArm3_plast_link_joint" type="revolute">
    <limit lower="-1.83400" upper="1.83400" effort="0.00000" velocity="0.00000"/>
    <origin rpy="0.00000 0.00000 0.00000" xyz="0.00000 0.00000 -3.20000"/>
    <parent link="leftArm2_plast_link"/>
    <child link="leftArm3_plast_link"/>
    <axis xyz="1.00000 0.00000 0.00000"/>
  </joint>
  <joint name="leftArm4_Joint" type="revolute">
    <limit lower="-0.05480" upper="0.05480" effort="0.00000" velocity="0.00000"/>
    <origin rpy="0.00000 0.00000 0.00000" xyz="-0.00000 -0.00000 -3.20000"/>
    <parent link="leftArm3_plast_link"/>
    <child link="leftArm4_link"/>
    <axis xyz="1.00000 0.00000 0.00000"/>
  </joint>
  <joint name="leftArm5_plast_link_joint" type="revolute">
    <limit lower="-1.83400" upper="1.83400" effort="0.00000" velocity="0.00000"/>
    <origin rpy="0.00000 0.00000 0.00000" xyz="0.00500 -0.00000 -1.32502"/>
    <parent link="leftArm4_link"/>
    <child link="leftArm5_plast_link"/>
    <axis xyz="0.00000 0.00000 1.00000"/>
  </joint>
  <joint name="neck_plast_link_joint" type="revolute">
    <limit lower="-1.83400" upper="1.83400" effort="0.00000" velocity="0.00000"/>
    <origin rpy="0.00000 0.00000 0.00000" xyz="-0.50000 18.26999 -0.00000"/>
    <parent link="body0_plast_white_link"/>
    <child link="neck_plast_link"/>
    <axis xyz="0.00000 1.00000 0.00000"/>
  </joint>
  <joint name="rArmEff_Link" type="revolute">
    <limit lower="-0.05480" upper="0.05480" effort="0.00000" velocity="0.00000"/>
    <origin rpy="0.00000 0.00000 0.00000" xyz="0.00000 1.90250 -0.00500"/>
    <parent link="neck_plast_link"/>
    <child link="head_steel_link"/>
    <axis xyz="0.00000 0.00000 1.00000"/>
  </joint>
  <joint name="rArmEff_joint" type="revolute">
    <limit lower="-3.14000" upper="3.14000" effort="0.00000" velocity="0.00000"/>
    <origin rpy="0.00000 0.00000 0.00000" xyz="0.50000 0.00000 2.89749"/>
    <parent link="rightArm5_red_link"/>
    <child link="rArmEff_link"/>
    <axis xyz="0.00000 1.00000 0.00000"/>
  </joint>
  <joint name="rightArm1_link_joint" type="revolute">
    <limit lower="-0.26000" upper="3.10000" effort="0.00000" velocity="0.00000"/>
    <origin rpy="0.00000 0.00000 0.00000" xyz="0.00000 17.49999 6.17249"/>
    <parent link="body0_plast_white_link"/>
    <child link="rightArm1_steel_link"/>
    <axis xyz="0.00000 0.00000 1.00000"/>
  </joint>
  <joint name="rightArm2_link_joint" type="revolute">
    <limit lower="-1.83400" upper="1.83400" effort="0.00000" velocity="0.00000"/>
    <origin rpy="0.00000 0.00000 0.00000" xyz="-0.00500 0.00000 1.87501"/>
    <parent link="rightArm1_steel_link"/>
    <child link="rightArm2_steel_link"/>
    <axis xyz="1.00000 0.00000 0.00000"/>
  </joint>
  <joint name="rightArm3_link_joint" type="revolute">
    <limit lower="-1.83400" upper="1.83400" effort="0.00000" velocity="0.00000"/>
    <origin rpy="0.00000 0.00000 0.00000" xyz="-0.00000 0.00000 3.20000"/>
    <parent link="rightArm2_steel_link"/>
    <child link="rightArm3_steel_link"/>
    <axis xyz="1.00000 0.00000 0.00000"/>
  </joint>
  <joint name="rightArm4_link_joint" type="revolute">
    <limit lower="-1.83400" upper="1.83400" effort="0.00000" velocity="0.00000"/>
    <origin rpy="0.00000 0.00000 0.00000" xyz="-0.00000 0.00000 3.19999"/>
    <parent link="rightArm3_steel_link"/>
    <child link="rightArm4_link"/>
    <axis xyz="1.00000 0.00000 0.00000"/>
  </joint>
  <joint name="rightArm5_plast_link_joint" type="revolute">
    <limit lower="-1.83400" upper="1.83400" effort="0.00000" velocity="0.00000"/>
    <origin rpy="0.00000 0.00000 0.00000" xyz="0.00500 0.00000 1.32502"/>
    <parent link="rightArm4_link"/>
    <child link="rightArm5_red_link"/>
    <axis xyz="0.00000 0.00000 1.00000"/>
  </joint>
  <link name="HeadEff_link">
    <visual name="headEffCube">
      <origin rpy="0.00000 0.00000 0.00000" xyz="0.00000 0.00000 0.00000"/>
      <geometry>
        <mesh filename="../meshes/stl/Cube.040.stl" scale="1.00000 1.00000 1.00000"/>
      </geometry>
    </visual>
  </link>
  <link name="body0_plast_white_link">
    <collision name="body0_coll_big">
      <origin rpy="0.00000 0.00000 0.00000" xyz="-0.09935 9.56619 0.00012"/>
      <geometry>
        <mesh filename="../meshes/stl/Cube.stl" scale="1.00000 1.00000 1.00000"/>
      </geometry>
    </collision>
    <visual name="body0_plast_white">
      <origin rpy="0.00000 0.00000 0.00000" xyz="0.00000 0.00000 0.00000"/>
      <material name="white"/>
      <geometry>
        <mesh filename="../meshes/stl/body_white.stl" scale="1.00000 1.00000 1.00000"/>
      </geometry>
    </visual>
    <visual name="body_plast">
      <origin rpy="0.00000 0.00000 0.00000" xyz="0.00000 0.00000 0.00000"/>
      <material name="black"/>
      <geometry>
        <mesh filename="../meshes/stl/body_black.stl" scale="1.00000 1.00000 1.00000"/>
      </geometry>
    </visual>
    <visual name="body_plast_red">
      <origin rpy="0.00000 0.00000 0.00000" xyz="0.00000 0.00000 0.00000"/>
      <material name="red"/>
      <geometry>
        <mesh filename="../meshes/stl/body_red.stl" scale="1.00000 1.00000 1.00000"/>
      </geometry>
    </visual>
  </link>
  <link name="head_steel_link">
    <collision name="head_coll_big">
      <origin rpy="0.00000 0.00000 0.00000" xyz="-0.28471 4.38254 0.00500"/>
      <geometry>
        <mesh filename="../meshes/stl/Cube.004.stl" scale="1.00000 1.00000 1.00000"/>
      </geometry>
    </collision>
    <visual name="head_plast">
      <origin rpy="0.00000 0.00000 0.00000" xyz="0.00000 1.32502 0.00500"/>
      <material name="whiteHead"/>
      <geometry>
        <mesh filename="../meshes/stl/head_white.stl" scale="1.00000 1.00000 1.00000"/>
      </geometry>
    </visual>
    <visual name="head_screen">
      <origin rpy="0.00000 0.00000 0.00000" xyz="0.00000 1.32502 0.00500"/>
      <material name="black"/>
      <geometry>
        <mesh filename="../meshes/stl/head_black.stl" scale="1.00000 1.00000 1.00000"/>
      </geometry>
    </visual>
    <visual name="head_steel">
      <origin rpy="0.00000 0.00000 0.00000" xyz="0.00000 0.00000 0.00000"/>
      <material name="steel"/>
      <geometry>
        <mesh filename="../meshes/stl/head_steel.stl" scale="1.00000 1.00000 1.00000"/>
      </geometry>
    </visual>
  </link>
  <link name="lArmEff_link">
    <visual name="lEndEffCube">
      <origin rpy="0.00000 0.00000 0.00000" xyz="0.00000 0.00000 0.00000"/>
      <material name="blackLa"/>
      <geometry>
        <mesh filename="../meshes/stl/LAP5.001.stl" scale="1.00000 1.00000 1.00000"/>
      </geometry>
    </visual>
  </link>
  <link name="leftArm1_plast_link">
    <visual name="leftArm1_plast">
      <origin rpy="0.00000 0.00000 0.00000" xyz="0.00000 0.00000 0.00000"/>
      <material name="black"/>
      <geometry>
        <mesh filename="../meshes/stl/LAP1.stl" scale="1.00000 1.00000 1.00000"/>
      </geometry>
    </visual>
    <visual name="leftArm1_red">
      <origin rpy="0.00000 0.00000 0.00000" xyz="0.00000 -0.00000 0.00000"/>
      <material name="red"/>
      <geometry>
        <mesh filename="../meshes/stl/LAR1.stl" scale="1.00000 1.00000 1.00000"/>
      </geometry>
    </visual>
    <visual name="leftArm1_steel">
      <origin rpy="0.00000 0.00000 0.00000" xyz="0.00000 -0.00000 0.00000"/>
      <material name="steel"/>
      <geometry>
        <mesh filename="../meshes/stl/LAS1.stl" scale="1.00000 1.00000 1.00000"/>
      </geometry>
    </visual>
  </link>
  <link name="leftArm2_plast_link">
    <visual name="leftArm2_plast">
      <origin rpy="0.00000 0.00000 0.00000" xyz="0.00000 0.00000 0.00000"/>
      <material name="black"/>
      <geometry>
        <mesh filename="../meshes/stl/LAP2.stl" scale="1.00000 1.00000 1.00000"/>
      </geometry>
    </visual>
    <visual name="leftArm2_red">
      <origin rpy="0.00000 0.00000 0.00000" xyz="0.00000 0.00000 0.00000"/>
      <material name="red"/>
      <geometry>
        <mesh filename="../meshes/stl/LAR2.stl" scale="1.00000 1.00000 1.00000"/>
      </geometry>
    </visual>
    <visual name="leftArm2_steel">
      <origin rpy="0.00000 0.00000 0.00000" xyz="0.00000 0.00000 0.00000"/>
      <material name="steel"/>
      <geometry>
        <mesh filename="../meshes/stl/LAS2.stl" scale="1.00000 1.00000 1.00000"/>
      </geometry>
    </visual>
  </link>
  <link name="leftArm3_plast_link">
    <visual name="leftArm3_plast">
      <origin rpy="0.00000 0.00000 0.00000" xyz="-0.00000 0.00000 0.00000"/>
      <material name="black"/>
      <geometry>
        <mesh filename="../meshes/stl/LAP3.stl" scale="1.00000 1.00000 1.00000"/>
      </geometry>
    </visual>
    <visual name="leftArm3_red">
      <origin rpy="0.00000 0.00000 0.00000" xyz="-0.00000 -0.00000 0.00000"/>
      <material name="red"/>
      <geometry>
        <mesh filename="../meshes/stl/LAR3.stl" scale="1.00000 1.00000 1.00000"/>
      </geometry>
    </visual>
    <visual name="leftArm3_steel">
      <origin rpy="0.00000 0.00000 0.00000" xyz="-0.00000 -0.00000 0.00000"/>
      <material name="steel"/>
      <geometry>
        <mesh filename="../meshes/stl/LAS3.stl" scale="1.00000 1.00000 1.00000"/>
      </geometry>
    </visual>
  </link>
  <link name="leftArm4_link">
    <visual name="leftArm4">
      <origin rpy="0.00000 0.00000 0.00000" xyz="0.00000 0.00000 0.00000"/>
      <material name="steel"/>
      <geometry>
        <mesh filename="../meshes/stl/LAS4.stl" scale="1.00000 1.00000 1.00000"/>
      </geometry>
    </visual>
  </link>
  <link name="leftArm5_plast_link">
    <visual name="leftArm5_plast">
      <origin rpy="0.00000 0.00000 0.00000" xyz="0.00000 0.00000 0.00000"/>
      <material name="blackLa"/>
      <geometry>
        <mesh filename="../meshes/stl/LAP5.stl" scale="1.00000 1.00000 1.00000"/>
      </geometry>
    </visual>
    <visual name="leftArm5_red">
      <origin rpy="0.00000 0.00000 0.00000" xyz="0.00000 0.00000 0.00000"/>
      <material name="red"/>
      <geometry>
        <mesh filename="../meshes/stl/LAR5.stl" scale="1.00000 1.00000 1.00000"/>
      </geometry>
    </visual>
  </link>
  <link name="neck_plast_link">
    <visual name="neck_plast">
      <origin rpy="0.00000 0.00000 0.00000" xyz="0.00000 0.00000 0.00000"/>
      <material name="black"/>
      <geometry>
        <mesh filename="../meshes/stl/NP.stl" scale="1.00000 1.00000 1.00000"/>
      </geometry>
    </visual>
    <visual name="neck_red">
      <origin rpy="0.00000 0.00000 0.00000" xyz="0.00000 0.00000 0.00000"/>
      <material name="red"/>
      <geometry>
        <mesh filename="../meshes/stl/NR.stl" scale="1.00000 1.00000 1.00000"/>
      </geometry>
    </visual>
    <visual name="neck_steel">
      <origin rpy="0.00000 0.00000 0.00000" xyz="0.00000 0.00000 0.00000"/>
      <material name="steel"/>
      <geometry>
        <mesh filename="../meshes/stl/NS.stl" scale="1.00000 1.00000 1.00000"/>
      </geometry>
    </visual>
  </link>
  <link name="rArmEff_link">
    <visual name="rEndEffCube">
      <origin rpy="-1.57080 0.00000 0.00000" xyz="0.00000 0.00000 0.00000"/>
      <geometry>
        <mesh filename="../meshes/stl/Cube.001.stl" scale="1.00000 1.00000 1.00000"/>
      </geometry>
    </visual>
  </link>
  <link name="rightArm1_steel_link">
    <visual name="rightArm1_plast">
      <origin rpy="0.00000 0.00000 0.00000" xyz="0.00000 0.00000 0.00000"/>
      <material name="black"/>
      <geometry>
        <mesh filename="../meshes/stl/RAP1.stl" scale="1.00000 1.00000 1.00000"/>
      </geometry>
    </visual>
    <visual name="rightArm1_red">
      <origin rpy="0.00000 0.00000 0.00000" xyz="0.00000 0.00000 0.00000"/>
      <material name="red"/>
      <geometry>
        <mesh filename="../meshes/stl/RAR1.stl" scale="1.00000 1.00000 1.00000"/>
      </geometry>
    </visual>
    <visual name="rightArm1_steel">
      <origin rpy="0.00000 0.00000 0.00000" xyz="0.00000 0.00000 0.00000"/>
      <material name="steel"/>
      <geometry>
        <mesh filename="../meshes/stl/RAS1.stl" scale="1.00000 1.00000 1.00000"/>
      </geometry>
    </visual>
  </link>
  <link name="rightArm2_steel_link">
    <visual name="rightArm2_plast">
      <origin rpy="0.00000 0.00000 0.00000" xyz="0.00000 0.00000 0.00000"/>
      <material name="black"/>
      <geometry>
        <mesh filename="../meshes/stl/RAP2.stl" scale="1.00000 1.00000 1.00000"/>
      </geometry>
    </visual>
    <visual name="rightArm2_red">
      <origin rpy="0.00000 0.00000 0.00000" xyz="0.00000 0.00000 0.00000"/>
      <material name="red"/>
      <geometry>
        <mesh filename="../meshes/stl/RAR2.stl" scale="1.00000 1.00000 1.00000"/>
      </geometry>
    </visual>
    <visual name="rightArm2_steel">
      <origin rpy="0.00000 0.00000 0.00000" xyz="0.00000 0.00000 0.00000"/>
      <material name="steel"/>
      <geometry>
        <mesh filename="../meshes/stl/RAS2.stl" scale="1.00000 1.00000 1.00000"/>
      </geometry>
    </visual>
  </link>
  <link name="rightArm3_steel_link">
    <visual name="rightArm3_plast">
      <origin rpy="0.00000 0.00000 0.00000" xyz="-0.00000 0.00000 0.00000"/>
      <material name="black"/>
      <geometry>
        <mesh filename="../meshes/stl/RAP3.stl" scale="1.00000 1.00000 1.00000"/>
      </geometry>
    </visual>
    <visual name="rightArm3_red">
      <origin rpy="0.00000 0.00000 0.00000" xyz="-0.00000 0.00000 0.00000"/>
      <material name="red"/>
      <geometry>
        <mesh filename="../meshes/stl/RAR3.stl" scale="1.00000 1.00000 1.00000"/>
      </geometry>
    </visual>
    <visual name="rightArm3_steel">
      <origin rpy="0.00000 0.00000 0.00000" xyz="-0.00000 0.00000 0.00000"/>
      <material name="steel"/>
      <geometry>
        <mesh filename="../meshes/stl/RAS3.stl" scale="1.00000 1.00000 1.00000"/>
      </geometry>
    </visual>
  </link>
  <link name="rightArm4_link">
    <visual name="rightArm4">
      <origin rpy="0.00000 0.00000 0.00000" xyz="0.00000 0.00000 0.00000"/>
      <material name="steel"/>
      <geometry>
        <mesh filename="../meshes/stl/RAS4.stl" scale="1.00000 1.00000 1.00000"/>
      </geometry>
    </visual>
  </link>
  <link name="rightArm5_red_link">
    <visual name="rightArm5_plast">
      <origin rpy="0.00000 0.00000 0.00000" xyz="0.00000 0.00000 0.00000"/>
      <material name="blackRarm"/>
      <geometry>
        <mesh filename="../meshes/stl/RAP5.stl" scale="1.00000 1.00000 1.00000"/>
      </geometry>
    </visual>
    <visual name="rightArm5_red">
      <origin rpy="0.00000 0.00000 0.00000" xyz="0.00000 0.00000 0.00000"/>
      <material name="red"/>
      <geometry>
        <mesh filename="../meshes/stl/RAR5.stl" scale="1.00000 1.00000 1.00000"/>
      </geometry>
    </visual>
  </link>
  <material name="black">
    <color rgba="0.01569 0.01569 0.01569 1.00000"/>
  </material>
  <material name="blackLa">
    <color rgba="0.01569 0.01569 0.01569 1.00000"/>
  </material>
  <material name="blackRarm">
    <color rgba="0.01569 0.01569 0.01569 1.00000"/>
  </material>
  <material name="red">
    <color rgba="0.80000 0.00000 0.00000 1.00000"/>
  </material>
  <material name="steel">
    <color rgba="0.21569 0.21569 0.21569 1.00000"/>
  </material>
  <material name="white">
    <color rgba="1.00000 1.00000 1.00000 1.00000"/>
  </material>
  <material name="whiteHead">
    <color rgba="1.00000 1.00000 1.00000 1.00000"/>
  </material>
</robot>