<sdf version="1.9">
<model name="bobot" canonical_link="body0_plast_white_link">
  <joint name="head_steel_link_joint" type="revolute">
    <pose relative_to="neck_plast_link">0.00000 1.90250 -0.00500 0.00000 0.00000 0.00000</pose>
    <parent>neck_plast_link</parent>
    <child>head_steel_link</child>
    <axis>
      <limit>
        <lower>-0.70000</lower>
        <upper>0.70000</upper>
        <effort>0.00000</effort>
        <velocity>0.00000</velocity>
      </limit>
      <xyz>0.00000 0.00000 1.00000</xyz>
    </axis>
  </joint>
  <joint name="leftArm1_plast_link_joint" type="revolute">
    <pose relative_to="body0_plast_white_link">-0.00000 17.49999 -6.17249 0.00000 0.00000 0.00000</pose>
    <parent>body0_plast_white_link</parent>
    <child>leftArm1_plast_link</child>
    <axis>
      <limit>
        <lower>-0.26000</lower>
        <upper>3.40000</upper>
        <effort>0.00000</effort>
        <velocity>0.00000</velocity>
      </limit>
      <xyz>0.00000 0.00000 1.00000</xyz>
    </axis>
  </joint>
  <joint name="leftArm2_plast_link_joint" type="revolute">
    <pose relative_to="leftArm1_plast_link">0.00000 -0.00500 -1.87501 0.00000 0.00000 0.00000</pose>
    <parent>leftArm1_plast_link</parent>
    <child>leftArm2_plast_link</child>
    <axis>
      <limit>
        <lower>-1.83400</lower>
        <upper>1.83400</upper>
        <effort>0.00000</effort>
        <velocity>0.00000</velocity>
      </limit>
      <xyz>1.00000 0.00000 0.00000</xyz>
    </axis>
  </joint>
  <joint name="leftArm3_plast_link_joint" type="revolute">
    <pose relative_to="leftArm2_plast_link">0.00000 0.00000 -3.20000 0.00000 0.00000 0.00000</pose>
    <parent>leftArm2_plast_link</parent>
    <child>leftArm3_plast_link</child>
    <axis>
      <limit>
        <lower>-1.83400</lower>
        <upper>1.83400</upper>
        <effort>0.00000</effort>
        <velocity>0.00000</velocity>
      </limit>
      <xyz>1.00000 0.00000 0.00000</xyz>
    </axis>
  </joint>
  <joint name="leftArm4_link_joint" type="revolute">
    <pose relative_to="leftArm3_plast_link">-0.00000 -0.00000 -3.20000 0.00000 0.00000 0.00000</pose>
    <parent>leftArm3_plast_link</parent>
    <child>leftArm4_link</child>
    <axis>
      <limit>
        <lower>-1.83400</lower>
        <upper>1.83400</upper>
        <effort>0.00000</effort>
        <velocity>0.00000</velocity>
      </limit>
      <xyz>1.00000 0.00000 0.00000</xyz>
    </axis>
  </joint>
  <joint name="leftArm5_plast_link_joint" type="revolute">
    <pose relative_to="leftArm4_link">0.00500 -0.00000 -1.32502 0.00000 0.00000 0.00000</pose>
    <parent>leftArm4_link</parent>
    <child>leftArm5_plast_link</child>
    <axis>
      <limit>
        <lower>-1.83400</lower>
        <upper>1.83400</upper>
        <effort>0.00000</effort>
        <velocity>0.00000</velocity>
      </limit>
      <xyz>0.00000 0.00000 1.00000</xyz>
    </axis>
  </joint>
  <joint name="neck_plast_link_joint" type="revolute">
    <pose relative_to="body0_plast_white_link">-0.50000 18.26999 -0.00000 0.00000 0.00000 0.00000</pose>
    <parent>body0_plast_white_link</parent>
    <child>neck_plast_link</child>
    <axis>
      <limit>
        <lower>-1.83400</lower>
        <upper>1.83400</upper>
        <effort>0.00000</effort>
        <velocity>0.00000</velocity>
      </limit>
      <xyz>0.00000 1.00000 0.00000</xyz>
    </axis>
  </joint>
  <joint name="rArmEff_Link" type="revolute">
    <pose relative_to="rightArm5_red_link">0.50000 0.00000 2.29749 0.00000 0.00000 0.00000</pose>
    <parent>rightArm5_red_link</parent>
    <child>Armature</child>
    <axis>
      <limit>
        <lower>-3.14000</lower>
        <upper>3.14000</upper>
        <effort>0.00000</effort>
        <velocity>0.00000</velocity>
      </limit>
      <xyz>0.00000 1.00000 0.00000</xyz>
    </axis>
  </joint>
  <joint name="rightArm1_link_joint" type="revolute">
    <pose relative_to="body0_plast_white_link">0.00000 17.49999 6.17249 0.00000 0.00000 0.00000</pose>
    <parent>body0_plast_white_link</parent>
    <child>rightArm1_steel_link</child>
    <axis>
      <limit>
        <lower>-0.26000</lower>
        <upper>3.10000</upper>
        <effort>0.00000</effort>
        <velocity>0.00000</velocity>
      </limit>
      <xyz>0.00000 0.00000 1.00000</xyz>
    </axis>
  </joint>
  <joint name="rightArm2_link_joint" type="revolute">
    <pose relative_to="rightArm1_steel_link">-0.00500 0.00000 1.87501 0.00000 0.00000 0.00000</pose>
    <parent>rightArm1_steel_link</parent>
    <child>rightArm2_steel_link</child>
    <axis>
      <limit>
        <lower>-1.83400</lower>
        <upper>1.83400</upper>
        <effort>0.00000</effort>
        <velocity>0.00000</velocity>
      </limit>
      <xyz>1.00000 0.00000 0.00000</xyz>
    </axis>
  </joint>
  <joint name="rightArm3_link_joint" type="revolute">
    <pose relative_to="rightArm2_steel_link">-0.00000 0.00000 3.20000 0.00000 0.00000 0.00000</pose>
    <parent>rightArm2_steel_link</parent>
    <child>rightArm3_steel_link</child>
    <axis>
      <limit>
        <lower>-1.83400</lower>
        <upper>1.83400</upper>
        <effort>0.00000</effort>
        <velocity>0.00000</velocity>
      </limit>
      <xyz>1.00000 0.00000 0.00000</xyz>
    </axis>
  </joint>
  <joint name="rightArm4_link_joint" type="revolute">
    <pose relative_to="rightArm3_steel_link">-0.00000 0.00000 3.19999 0.00000 0.00000 0.00000</pose>
    <parent>rightArm3_steel_link</parent>
    <child>rightArm4_link</child>
    <axis>
      <limit>
        <lower>-1.83400</lower>
        <upper>1.83400</upper>
        <effort>0.00000</effort>
        <velocity>0.00000</velocity>
      </limit>
      <xyz>1.00000 0.00000 0.00000</xyz>
    </axis>
  </joint>
  <joint name="rightArm5_plast_link_joint" type="revolute">
    <pose relative_to="rightArm4_link">0.00500 0.00000 1.32502 0.00000 0.00000 0.00000</pose>
    <parent>rightArm4_link</parent>
    <child>rightArm5_red_link</child>
    <axis>
      <limit>
        <lower>-1.83400</lower>
        <upper>1.83400</upper>
        <effort>0.00000</effort>
        <velocity>0.00000</velocity>
      </limit>
      <xyz>0.00000 0.00000 1.00000</xyz>
    </axis>
  </joint>
  <link name="Armature">
    <pose relative_to="rArmEff_Link">0.00000 0.00000 0.00000 0.00000 0.00000 0.00000</pose>
    <visual name="rArmEffjoint">
      <pose relative_to="Armature">0.00000 0.00000 -0.00000 -1.57080 0.00000 0.00000</pose>
      <geometry>
        <mesh>
          <uri>../meshes/stl/Cube.001.stl</uri>
          <scale>1.00000 1.00000 1.00000</scale>
        </mesh>
      </geometry>
    </visual>
  </link>
  <link name="body0_plast_white_link">
    <collision name="body0_coll_big">
      <pose relative_to="body0_plast_white_link">-0.09935 9.56619 0.00012 0.00000 0.00000 0.00000</pose>
      <geometry>
        <mesh>
          <uri>../meshes/stl/Cube.stl</uri>
          <scale>1.00000 1.00000 1.00000</scale>
        </mesh>
      </geometry>
      <surface>
        <contact/>
      </surface>
    </collision>
    <visual name="body0_plast_white">
      <material>
        <diffuse>1.00000 1.00000 1.00000 1.00000</diffuse>
        <specular>0.32941 0.32941 0.32941 0.32941</specular>
        <emissive>0.00000 0.00000 0.00000 1.00000</emissive>
      </material>
      <pose relative_to="body0_plast_white_link">0.00000 0.00000 0.00000 0.00000 0.00000 0.00000</pose>
      <geometry>
        <mesh>
          <uri>../meshes/stl/body_white.stl</uri>
          <scale>1.00000 1.00000 1.00000</scale>
        </mesh>
      </geometry>
    </visual>
    <visual name="body_plast">
      <material>
        <diffuse>0.01569 0.01569 0.01569 1.00000</diffuse>
        <specular>0.00784 0.00784 0.00784 0.49804</specular>
        <emissive>0.00000 0.00000 0.00000 1.00000</emissive>
      </material>
      <pose relative_to="body0_plast_white_link">0.00000 0.00000 0.00000 0.00000 0.00000 0.00000</pose>
      <geometry>
        <mesh>
          <uri>../meshes/stl/body_black.stl</uri>
          <scale>1.00000 1.00000 1.00000</scale>
        </mesh>
      </geometry>
    </visual>
    <visual name="body_plast_red">
      <material>
        <diffuse>0.80000 0.00000 0.00000 1.00000</diffuse>
        <specular>0.40000 0.00000 0.00000 0.49804</specular>
        <emissive>0.00000 0.00000 0.00000 1.00000</emissive>
      </material>
      <pose relative_to="body0_plast_white_link">0.00000 0.00000 0.00000 0.00000 0.00000 0.00000</pose>
      <geometry>
        <mesh>
          <uri>../meshes/stl/body_red.stl</uri>
          <scale>1.00000 1.00000 1.00000</scale>
        </mesh>
      </geometry>
    </visual>
  </link>
  <link name="head_steel_link">
    <collision name="head_coll_big">
      <pose relative_to="head_steel_link">-0.28471 4.38254 0.00500 0.00000 0.00000 0.00000</pose>
      <geometry>
        <mesh>
          <uri>../meshes/stl/Cube.004.stl</uri>
          <scale>1.00000 1.00000 1.00000</scale>
        </mesh>
      </geometry>
      <surface>
        <contact/>
      </surface>
    </collision>
    <pose relative_to="head_steel_link_joint">0.00000 0.00000 0.00000 0.00000 0.00000 0.00000</pose>
    <visual name="head_plast">
      <material>
        <diffuse>1.00000 1.00000 1.00000 1.00000</diffuse>
        <specular>0.32941 0.32941 0.32941 0.32941</specular>
        <emissive>0.00000 0.00000 0.00000 1.00000</emissive>
      </material>
      <pose relative_to="head_steel_link">0.00000 1.32502 0.00500 0.00000 0.00000 0.00000</pose>
      <geometry>
        <mesh>
          <uri>../meshes/stl/head_white.stl</uri>
          <scale>1.00000 1.00000 1.00000</scale>
        </mesh>
      </geometry>
    </visual>
    <visual name="head_screen">
      <material>
        <diffuse>0.01569 0.01569 0.01569 1.00000</diffuse>
        <specular>0.00784 0.00784 0.00784 0.49804</specular>
        <emissive>0.00000 0.00000 0.00000 1.00000</emissive>
      </material>
      <pose relative_to="head_steel_link">0.00000 1.32502 0.00500 0.00000 0.00000 0.00000</pose>
      <geometry>
        <mesh>
          <uri>../meshes/stl/head_black.stl</uri>
          <scale>1.00000 1.00000 1.00000</scale>
        </mesh>
      </geometry>
    </visual>
    <visual name="head_steel">
      <material>
        <diffuse>0.21569 0.21569 0.21569 1.00000</diffuse>
        <specular>0.07059 0.07059 0.07059 0.32941</specular>
        <emissive>0.00000 0.00000 0.00000 1.00000</emissive>
      </material>
      <pose relative_to="head_steel_link">0.00000 0.00000 0.00000 0.00000 0.00000 0.00000</pose>
      <geometry>
        <mesh>
          <uri>../meshes/stl/head_steel.stl</uri>
          <scale>1.00000 1.00000 1.00000</scale>
        </mesh>
      </geometry>
    </visual>
  </link>
  <link name="leftArm1_plast_link">
    <pose relative_to="leftArm1_plast_link_joint">0.00000 0.00000 0.00000 0.00000 0.00000 0.00000</pose>
    <visual name="leftArm1_plast">
      <material>
        <diffuse>0.01569 0.01569 0.01569 1.00000</diffuse>
        <specular>0.00784 0.00784 0.00784 0.49804</specular>
        <emissive>0.00000 0.00000 0.00000 1.00000</emissive>
      </material>
      <pose relative_to="leftArm1_plast_link">0.00000 0.00000 0.00000 0.00000 0.00000 0.00000</pose>
      <geometry>
        <mesh>
          <uri>../meshes/stl/LAP1.stl</uri>
          <scale>1.00000 1.00000 1.00000</scale>
        </mesh>
      </geometry>
    </visual>
    <visual name="leftArm1_red">
      <material>
        <diffuse>0.80000 0.00000 0.00000 1.00000</diffuse>
        <specular>0.40000 0.00000 0.00000 0.49804</specular>
        <emissive>0.00000 0.00000 0.00000 1.00000</emissive>
      </material>
      <pose relative_to="leftArm1_plast_link">0.00000 -0.00000 0.00000 0.00000 0.00000 0.00000</pose>
      <geometry>
        <mesh>
          <uri>../meshes/stl/LAR1.stl</uri>
          <scale>1.00000 1.00000 1.00000</scale>
        </mesh>
      </geometry>
    </visual>
    <visual name="leftArm1_steel">
      <material>
        <diffuse>0.21569 0.21569 0.21569 1.00000</diffuse>
        <specular>0.07059 0.07059 0.07059 0.32941</specular>
        <emissive>0.00000 0.00000 0.00000 1.00000</emissive>
      </material>
      <pose relative_to="leftArm1_plast_link">0.00000 -0.00000 0.00000 0.00000 0.00000 0.00000</pose>
      <geometry>
        <mesh>
          <uri>../meshes/stl/LAS1.stl</uri>
          <scale>1.00000 1.00000 1.00000</scale>
        </mesh>
      </geometry>
    </visual>
  </link>
  <link name="leftArm2_plast_link">
    <pose relative_to="leftArm2_plast_link_joint">0.00000 0.00000 0.00000 0.00000 0.00000 0.00000</pose>
    <visual name="leftArm2_plast">
      <material>
        <diffuse>0.01569 0.01569 0.01569 1.00000</diffuse>
        <specular>0.00784 0.00784 0.00784 0.49804</specular>
        <emissive>0.00000 0.00000 0.00000 1.00000</emissive>
      </material>
      <pose relative_to="leftArm2_plast_link">0.00000 0.00000 0.00000 0.00000 0.00000 0.00000</pose>
      <geometry>
        <mesh>
          <uri>../meshes/stl/LAP2.stl</uri>
          <scale>1.00000 1.00000 1.00000</scale>
        </mesh>
      </geometry>
    </visual>
    <visual name="leftArm2_red">
      <material>
        <diffuse>0.80000 0.00000 0.00000 1.00000</diffuse>
        <specular>0.40000 0.00000 0.00000 0.49804</specular>
        <emissive>0.00000 0.00000 0.00000 1.00000</emissive>
      </material>
      <pose relative_to="leftArm2_plast_link">0.00000 0.00000 0.00000 0.00000 0.00000 0.00000</pose>
      <geometry>
        <mesh>
          <uri>../meshes/stl/LAR2.stl</uri>
          <scale>1.00000 1.00000 1.00000</scale>
        </mesh>
      </geometry>
    </visual>
    <visual name="leftArm2_steel">
      <material>
        <diffuse>0.21569 0.21569 0.21569 1.00000</diffuse>
        <specular>0.07059 0.07059 0.07059 0.32941</specular>
        <emissive>0.00000 0.00000 0.00000 1.00000</emissive>
      </material>
      <pose relative_to="leftArm2_plast_link">0.00000 0.00000 0.00000 0.00000 0.00000 0.00000</pose>
      <geometry>
        <mesh>
          <uri>../meshes/stl/LAS2.stl</uri>
          <scale>1.00000 1.00000 1.00000</scale>
        </mesh>
      </geometry>
    </visual>
  </link>
  <link name="leftArm3_plast_link">
    <pose relative_to="leftArm3_plast_link_joint">0.00000 0.00000 0.00000 0.00000 0.00000 0.00000</pose>
    <visual name="leftArm3_plast">
      <material>
        <diffuse>0.01569 0.01569 0.01569 1.00000</diffuse>
        <specular>0.00784 0.00784 0.00784 0.49804</specular>
        <emissive>0.00000 0.00000 0.00000 1.00000</emissive>
      </material>
      <pose relative_to="leftArm3_plast_link">-0.00000 0.00000 0.00000 0.00000 0.00000 0.00000</pose>
      <geometry>
        <mesh>
          <uri>../meshes/stl/LAP3.stl</uri>
          <scale>1.00000 1.00000 1.00000</scale>
        </mesh>
      </geometry>
    </visual>
    <visual name="leftArm3_red">
      <material>
        <diffuse>0.80000 0.00000 0.00000 1.00000</diffuse>
        <specular>0.40000 0.00000 0.00000 0.49804</specular>
        <emissive>0.00000 0.00000 0.00000 1.00000</emissive>
      </material>
      <pose relative_to="leftArm3_plast_link">-0.00000 -0.00000 0.00000 0.00000 0.00000 0.00000</pose>
      <geometry>
        <mesh>
          <uri>../meshes/stl/LAR3.stl</uri>
          <scale>1.00000 1.00000 1.00000</scale>
        </mesh>
      </geometry>
    </visual>
    <visual name="leftArm3_steel">
      <material>
        <diffuse>0.21569 0.21569 0.21569 1.00000</diffuse>
        <specular>0.07059 0.07059 0.07059 0.32941</specular>
        <emissive>0.00000 0.00000 0.00000 1.00000</emissive>
      </material>
      <pose relative_to="leftArm3_plast_link">-0.00000 -0.00000 0.00000 0.00000 0.00000 0.00000</pose>
      <geometry>
        <mesh>
          <uri>../meshes/stl/LAS3.stl</uri>
          <scale>1.00000 1.00000 1.00000</scale>
        </mesh>
      </geometry>
    </visual>
  </link>
  <link name="leftArm4_link">
    <pose relative_to="leftArm4_link_joint">0.00000 0.00000 0.00000 0.00000 0.00000 0.00000</pose>
    <visual name="leftArm4">
      <material>
        <diffuse>0.21569 0.21569 0.21569 1.00000</diffuse>
        <specular>0.07059 0.07059 0.07059 0.32941</specular>
        <emissive>0.00000 0.00000 0.00000 1.00000</emissive>
      </material>
      <pose relative_to="leftArm4_link">0.00000 0.00000 0.00000 0.00000 0.00000 0.00000</pose>
      <geometry>
        <mesh>
          <uri>../meshes/stl/LAS4.stl</uri>
          <scale>1.00000 1.00000 1.00000</scale>
        </mesh>
      </geometry>
    </visual>
  </link>
  <link name="leftArm5_plast_link">
    <pose relative_to="leftArm5_plast_link_joint">0.00000 0.00000 0.00000 0.00000 0.00000 0.00000</pose>
    <visual name="leftArm5_plast">
      <material>
        <diffuse>0.01569 0.01569 0.01569 1.00000</diffuse>
        <specular>0.00784 0.00784 0.00784 0.49804</specular>
        <emissive>0.00000 0.00000 0.00000 1.00000</emissive>
      </material>
      <pose relative_to="leftArm5_plast_link">0.00000 0.00000 0.00000 0.00000 0.00000 0.00000</pose>
      <geometry>
        <mesh>
          <uri>../meshes/stl/LAP5.stl</uri>
          <scale>1.00000 1.00000 1.00000</scale>
        </mesh>
      </geometry>
    </visual>
    <visual name="leftArm5_red">
      <material>
        <diffuse>0.80000 0.00000 0.00000 1.00000</diffuse>
        <specular>0.40000 0.00000 0.00000 0.49804</specular>
        <emissive>0.00000 0.00000 0.00000 1.00000</emissive>
      </material>
      <pose relative_to="leftArm5_plast_link">0.00000 0.00000 0.00000 0.00000 0.00000 0.00000</pose>
      <geometry>
        <mesh>
          <uri>../meshes/stl/LAR5.stl</uri>
          <scale>1.00000 1.00000 1.00000</scale>
        </mesh>
      </geometry>
    </visual>
  </link>
  <link name="neck_plast_link">
    <pose relative_to="neck_plast_link_joint">0.00000 0.00000 0.00000 0.00000 0.00000 0.00000</pose>
    <visual name="neck_plast">
      <material>
        <diffuse>0.01569 0.01569 0.01569 1.00000</diffuse>
        <specular>0.00784 0.00784 0.00784 0.49804</specular>
        <emissive>0.00000 0.00000 0.00000 1.00000</emissive>
      </material>
      <pose relative_to="neck_plast_link">0.00000 0.00000 0.00000 0.00000 0.00000 0.00000</pose>
      <geometry>
        <mesh>
          <uri>../meshes/stl/NP.stl</uri>
          <scale>1.00000 1.00000 1.00000</scale>
        </mesh>
      </geometry>
    </visual>
    <visual name="neck_red">
      <material>
        <diffuse>0.80000 0.00000 0.00000 1.00000</diffuse>
        <specular>0.40000 0.00000 0.00000 0.49804</specular>
        <emissive>0.00000 0.00000 0.00000 1.00000</emissive>
      </material>
      <pose relative_to="neck_plast_link">0.00000 0.00000 0.00000 0.00000 0.00000 0.00000</pose>
      <geometry>
        <mesh>
          <uri>../meshes/stl/NR.stl</uri>
          <scale>1.00000 1.00000 1.00000</scale>
        </mesh>
      </geometry>
    </visual>
    <visual name="neck_steel">
      <material>
        <diffuse>0.21569 0.21569 0.21569 1.00000</diffuse>
        <specular>0.07059 0.07059 0.07059 0.32941</specular>
        <emissive>0.00000 0.00000 0.00000 1.00000</emissive>
      </material>
      <pose relative_to="neck_plast_link">0.00000 0.00000 0.00000 0.00000 0.00000 0.00000</pose>
      <geometry>
        <mesh>
          <uri>../meshes/stl/NS.stl</uri>
          <scale>1.00000 1.00000 1.00000</scale>
        </mesh>
      </geometry>
    </visual>
  </link>
  <link name="rightArm1_steel_link">
    <pose relative_to="rightArm1_link_joint">0.00000 0.00000 0.00000 0.00000 0.00000 0.00000</pose>
    <visual name="rightArm1_plast">
      <material>
        <diffuse>0.01569 0.01569 0.01569 1.00000</diffuse>
        <specular>0.00784 0.00784 0.00784 0.49804</specular>
        <emissive>0.00000 0.00000 0.00000 1.00000</emissive>
      </material>
      <pose relative_to="rightArm1_steel_link">0.00000 0.00000 0.00000 0.00000 0.00000 0.00000</pose>
      <geometry>
        <mesh>
          <uri>../meshes/stl/RAP1.stl</uri>
          <scale>1.00000 1.00000 1.00000</scale>
        </mesh>
      </geometry>
    </visual>
    <visual name="rightArm1_red">
      <material>
        <diffuse>0.80000 0.00000 0.00000 1.00000</diffuse>
        <specular>0.40000 0.00000 0.00000 0.49804</specular>
        <emissive>0.00000 0.00000 0.00000 1.00000</emissive>
      </material>
      <pose relative_to="rightArm1_steel_link">0.00000 0.00000 0.00000 0.00000 0.00000 0.00000</pose>
      <geometry>
        <mesh>
          <uri>../meshes/stl/RAR1.stl</uri>
          <scale>1.00000 1.00000 1.00000</scale>
        </mesh>
      </geometry>
    </visual>
    <visual name="rightArm1_steel">
      <material>
        <diffuse>0.21569 0.21569 0.21569 1.00000</diffuse>
        <specular>0.07059 0.07059 0.07059 0.32941</specular>
        <emissive>0.00000 0.00000 0.00000 1.00000</emissive>
      </material>
      <pose relative_to="rightArm1_steel_link">0.00000 0.00000 0.00000 0.00000 0.00000 0.00000</pose>
      <geometry>
        <mesh>
          <uri>../meshes/stl/RAS1.stl</uri>
          <scale>1.00000 1.00000 1.00000</scale>
        </mesh>
      </geometry>
    </visual>
  </link>
  <link name="rightArm2_steel_link">
    <pose relative_to="rightArm2_link_joint">0.00000 0.00000 0.00000 0.00000 0.00000 0.00000</pose>
    <visual name="rightArm2_plast">
      <material>
        <diffuse>0.01569 0.01569 0.01569 1.00000</diffuse>
        <specular>0.00784 0.00784 0.00784 0.49804</specular>
        <emissive>0.00000 0.00000 0.00000 1.00000</emissive>
      </material>
      <pose relative_to="rightArm2_steel_link">0.00000 0.00000 0.00000 0.00000 0.00000 0.00000</pose>
      <geometry>
        <mesh>
          <uri>../meshes/stl/RAP2.stl</uri>
          <scale>1.00000 1.00000 1.00000</scale>
        </mesh>
      </geometry>
    </visual>
    <visual name="rightArm2_red">
      <material>
        <diffuse>0.80000 0.00000 0.00000 1.00000</diffuse>
        <specular>0.40000 0.00000 0.00000 0.49804</specular>
        <emissive>0.00000 0.00000 0.00000 1.00000</emissive>
      </material>
      <pose relative_to="rightArm2_steel_link">0.00000 0.00000 0.00000 0.00000 0.00000 0.00000</pose>
      <geometry>
        <mesh>
          <uri>../meshes/stl/RAR2.stl</uri>
          <scale>1.00000 1.00000 1.00000</scale>
        </mesh>
      </geometry>
    </visual>
    <visual name="rightArm2_steel">
      <material>
        <diffuse>0.21569 0.21569 0.21569 1.00000</diffuse>
        <specular>0.07059 0.07059 0.07059 0.32941</specular>
        <emissive>0.00000 0.00000 0.00000 1.00000</emissive>
      </material>
      <pose relative_to="rightArm2_steel_link">0.00000 0.00000 0.00000 0.00000 0.00000 0.00000</pose>
      <geometry>
        <mesh>
          <uri>../meshes/stl/RAS2.stl</uri>
          <scale>1.00000 1.00000 1.00000</scale>
        </mesh>
      </geometry>
    </visual>
  </link>
  <link name="rightArm3_steel_link">
    <pose relative_to="rightArm3_link_joint">0.00000 0.00000 0.00000 0.00000 0.00000 0.00000</pose>
    <visual name="rightArm3_plast">
      <material>
        <diffuse>0.01569 0.01569 0.01569 1.00000</diffuse>
        <specular>0.00784 0.00784 0.00784 0.49804</specular>
        <emissive>0.00000 0.00000 0.00000 1.00000</emissive>
      </material>
      <pose relative_to="rightArm3_steel_link">-0.00000 0.00000 0.00000 0.00000 0.00000 0.00000</pose>
      <geometry>
        <mesh>
          <uri>../meshes/stl/RAP3.stl</uri>
          <scale>1.00000 1.00000 1.00000</scale>
        </mesh>
      </geometry>
    </visual>
    <visual name="rightArm3_red">
      <material>
        <diffuse>0.80000 0.00000 0.00000 1.00000</diffuse>
        <specular>0.40000 0.00000 0.00000 0.49804</specular>
        <emissive>0.00000 0.00000 0.00000 1.00000</emissive>
      </material>
      <pose relative_to="rightArm3_steel_link">-0.00000 0.00000 0.00000 0.00000 0.00000 0.00000</pose>
      <geometry>
        <mesh>
          <uri>../meshes/stl/RAR3.stl</uri>
          <scale>1.00000 1.00000 1.00000</scale>
        </mesh>
      </geometry>
    </visual>
    <visual name="rightArm3_steel">
      <material>
        <diffuse>0.21569 0.21569 0.21569 1.00000</diffuse>
        <specular>0.07059 0.07059 0.07059 0.32941</specular>
        <emissive>0.00000 0.00000 0.00000 1.00000</emissive>
      </material>
      <pose relative_to="rightArm3_steel_link">-0.00000 0.00000 0.00000 0.00000 0.00000 0.00000</pose>
      <geometry>
        <mesh>
          <uri>../meshes/stl/RAS3.stl</uri>
          <scale>1.00000 1.00000 1.00000</scale>
        </mesh>
      </geometry>
    </visual>
  </link>
  <link name="rightArm4_link">
    <pose relative_to="rightArm4_link_joint">0.00000 0.00000 0.00000 0.00000 0.00000 0.00000</pose>
    <visual name="rightArm4">
      <material>
        <diffuse>0.21569 0.21569 0.21569 1.00000</diffuse>
        <specular>0.07059 0.07059 0.07059 0.32941</specular>
        <emissive>0.00000 0.00000 0.00000 1.00000</emissive>
      </material>
      <pose relative_to="rightArm4_link">0.00000 0.00000 0.00000 0.00000 0.00000 0.00000</pose>
      <geometry>
        <mesh>
          <uri>../meshes/stl/RAS4.stl</uri>
          <scale>1.00000 1.00000 1.00000</scale>
        </mesh>
      </geometry>
    </visual>
  </link>
  <link name="rightArm5_red_link">
    <pose relative_to="rightArm5_plast_link_joint">0.00000 0.00000 0.00000 0.00000 0.00000 0.00000</pose>
    <visual name="rightArm5_plast">
      <material>
        <diffuse>0.01569 0.01569 0.01569 1.00000</diffuse>
        <specular>0.00784 0.00784 0.00784 0.49804</specular>
        <emissive>0.00000 0.00000 0.00000 1.00000</emissive>
      </material>
      <pose relative_to="rightArm5_red_link">0.00000 0.00000 0.00000 0.00000 0.00000 0.00000</pose>
      <geometry>
        <mesh>
          <uri>../meshes/stl/RAP5.stl</uri>
          <scale>1.00000 1.00000 1.00000</scale>
        </mesh>
      </geometry>
    </visual>
    <visual name="rightArm5_red">
      <material>
        <diffuse>0.80000 0.00000 0.00000 1.00000</diffuse>
        <specular>0.40000 0.00000 0.00000 0.49804</specular>
        <emissive>0.00000 0.00000 0.00000 1.00000</emissive>
      </material>
      <pose relative_to="rightArm5_red_link">0.00000 0.00000 0.00000 0.00000 0.00000 0.00000</pose>
      <geometry>
        <mesh>
          <uri>../meshes/stl/RAR5.stl</uri>
          <scale>1.00000 1.00000 1.00000</scale>
        </mesh>
      </geometry>
    </visual>
  </link>
  <plugin filename="gz-sim-joint-position-controller-system" name="gz::sim::systems::JointPositionController">
    <joint_name>rArmEff_Link</joint_name>
    <p_gain>20.00000</p_gain>
    <i_gain>0.00000</i_gain>
    <d_gain>0.00000</d_gain>
  </plugin>
</model>
</sdf>